Workbook

Sheet MasterMaterials
A1: =IF(SUM(Table1[QBO Sheet Verification])<>0,"QBO IMPORT SHEET BROKEN","QBO IMPORT SHEET READY") -> QBO IMPORT SHEET READY
A2: Name | B2: ID | C2: Type | D2: Size | E2: Description | F2: Internal | G2: Units | H2: Round | I2: Cost | J2: Price | K2: FixedPrice | L2: Profit | M2: Ship | N2: Warranty | O2: LastEditDate | P2: QBO Sheet Verification
A3: 1.25" Poly Fitting | B3: NEW048 | E3: 1.25" Fitting, ea | G3: ea | H3: 0 | I3: 2.24 | J3: 5.88 | P3: =if(A3='QB Import materials'!A2,0,1) -> 0
A4: 1.25" Poly, Ft | B4: NEW047 | E4: 1.25" Poly, Ft. | G4: ft | H4: 0 | I4: 0.48 | J4: 1.18 | K4: Y | P4: =if(A4='QB Import materials'!A3,0,1) -> 0
A5: 1.25" Stretch Repair Coupling | B5: LMN42485636 | C5: H | E5: 1.25" Stretch Repair Coupling | G5: ea | H5: 0 | I5: 20.72 | J5: 23.83 | K5: Y | O5: 45518 | P5: =if(A5='QB Import materials'!A4,0,1) -> 0
A6: 1.5" Poly Fitting, ea | B6: LMN40150704 | C6: H | E6: 1.5" Poly Fitting, ea | G6: ea | H6: 0 | I6: 5.94 | J6: 13.19 | K6: Y | O6: 45988 | P6: =if(A6='QB Import materials'!A5,0,1) -> 0
A7: 1.5" Poly, ft | B7: LMN40150705 | C7: H | E7: 1.5" Poly, ft | G7: ft | H7: 0 | I7: 0.87 | J7: 1.87 | K7: Y | O7: 45988 | P7: =if(A7='QB Import materials'!A6,0,1) -> 0
A8: 1.5" Stretch Repair Coupling, ea | B8: LMN42486243 | C8: H | E8: 1.5" Stretch Repair Coupling, ea | G8: ea | H8: 0 | I8: 22.8 | J8: 26.22 | K8: Y | O8: 45988 | P8: =if(A8='QB Import materials'!A7,0,1) -> 0
A9: 1.5" Tie-In Assembly, ea | B9: LMN40150680 | C9: H | E9: 1.5" Tie-In Assembly, ea | G9: ea | H9: 0 | I9: 252.5 | J9: 504.99 | K9: Y | O9: 45988 | P9: =if(A9='QB Import materials'!A8,0,1) -> 0
A10: 1" Drip Valve, ea | B10: LMN40150676 | C10: H | E10: 1" Drip Valve, ea | G10: ea | H10: 0 | I10: 50.04 | J10: 97.75 | K10: Y | O10: 45988 | P10: =if(A10='QB Import materials'!A9,0,1) -> 0
A11: 1" Fitting, ea | B11: LMN40150670 | C11: H | E11: 1" Fitting, ea | G11: ea | H11: 0 | I11: 1.62 | J11: 3.6 | K11: Y | O11: 45988 | P11: =if(A11='QB Import materials'!A10,0,1) -> 0
A12: 1" Poly, ft | B12: LMN40150667 | C12: H | E12: 1" Poly, ft | G12: ft | H12: 0 | I12: 0.36 | J12: 0.74 | K12: Y | O12: 45988 | P12: =if(A12='QB Import materials'!A11,0,1) -> 0
A13: 1" Stretch Repair Coupling | B13: LMN42485635 | C13: H | E13: 1" Stretch Repair Coupling | G13: ea | H13: 0 | I13: 13.69 | J13: 15.74 | K13: Y | O13: 45518 | P13: =if(A13='QB Import materials'!A12,0,1) -> 0
A14: 1" Tie-In Assembly, ea | B14: LMN40150679 | C14: H | E14: 1" Tie-In Assembly, ea | G14: ea | H14: 0 | I14: 128.94 | J14: 204.53 | K14: Y | O14: 45988 | P14: =if(A14='QB Import materials'!A13,0,1) -> 0
A15: 1" Valve, ea | B15: LMN40150674 | C15: H | E15: 1" Valve, ea | G15: ea | H15: 0 | I15: 17.78 | J15: 35.56 | K15: Y | O15: 45988 | P15: =if(A15='QB Import materials'!A14,0,1) -> 0
A16: 1/2" Fitting, ea | B16: LMN40150665 | C16: H | E16: 1/2" Fitting, ea | G16: ea | H16: 0 | I16: 0.38 | J16: 1.69 | K16: Y | O16: 45988 | P16: =if(A16='QB Import materials'!A15,0,1) -> 0
A17: 1/2" Poly, ft | B17: LMN40150666 | C17: H | E17: 1/2" Poly, ft | G17: ft | H17: 0 | I17: 0.13 | J17: 0.49 | K17: Y | O17: 45989 | P17: =if(A17='QB Import materials'!A16,0,1) -> 0
A18: 1800 with Nozzle and Street L | B18: LMN41760317 | C18: H | E18: 1800 with Nozzle and Street L | G18: Each | H18: 0 | I18: 7.56 | J18: 12.64 | O18: 45404 | P18: =if(A18='QB Import materials'!A17,0,1) -> 0
A19: 2" Poly Fitting, ea | B19: LMN40150707 | C19: H | E19: 2" Poly Fitting, ea | G19: ea | H19: 0 | I19: 7.53 | J19: 16.71 | K19: Y | O19: 45988 | P19: =if(A19='QB Import materials'!A18,0,1) -> 0
A20: 2" Poly, ft | B20: LMN40150706 | C20: H | E20: 2" Poly, ft | G20: ft | H20: 0 | I20: 1.43 | J20: 3.01 | K20: Y | O20: 45988 | P20: =if(A20='QB Import materials'!A19,0,1) -> 0
A21: 2" PVC Fitting, ea | B21: NEW033 | C21: H | E21: 2" PVC Fitting, ea | G21: ea | H21: 0 | I21: 4.75 | J21: 12.09 | K21: Y | O21: 45988 | P21: =if(A21='QB Import materials'!A20,0,1) -> 0
A22: 2" Stretch Repair Coupling, ea | B22: LMN42487087 | C22: H | E22: 2" Stretch Repair Coupling, ea | G22: ea | H22: 0 | I22: 32.69 | J22: 37.59 | K22: Y | O22: 45988 | P22: =if(A22='QB Import materials'!A21,0,1) -> 0
A23: 3/4" Brass Quick Coupler, ea | B23: NEW034 | C23: H | E23: 3/4" Brass Quick Coupler, ea | G23: ea | H23: 0 | I23: 49.75 | J23: 97.95 | K23: Y | O23: 45988 | P23: =if(A23='QB Import materials'!A22,0,1) -> 0
A24: 4" Corrugated Drain Pipe, ft | B24: LMN40150730 | C24: H | E24: 4" Corrugated Drain Pipe, ft | G24: ft | H24: 0 | I24: 2.25 | J24: 4.5 | K24: Y | O24: 45988 | P24: =if(A24='QB Import materials'!A23,0,1) -> 0
A25: 4" Corrugated Fitting, ea | B25: LMN40150731 | C25: H | E25: 4" Corrugated Fitting, ea | G25: ea | H25: 0 | I25: 8.5 | J25: 14.21 | O25: 45988 | P25: =if(A25='QB Import materials'!A24,0,1) -> 0
A26: 4" PVC Sewer Fitting, ea | B26: LMN40150733 | C26: H | E26: 4" PVC Sewer Fitting, ea | G26: ea | H26: 0 | I26: 6.33 | J26: 10.58 | O26: 45988 | P26: =if(A26='QB Import materials'!A25,0,1) -> 0
A27: 4" PVC Sewer Pipe, ft | B27: LMN40150732 | C27: H | E27: 4" PVC Sewer Pipe, ft | G27: ft | H27: 0 | I27: 3.7 | J27: 6.18 | O27: 45988 | P27: =if(A27='QB Import materials'!A26,0,1) -> 0
A28: 5004 with Street L, ea | B28: LMN41760319 | C28: H | E28: 5004 with Street L, ea | G28: Each | H28: 0 | I28: 25 | J28: 41.79 | O28: 45404 | P28: =if(A28='QB Import materials'!A27,0,1) -> 0
A29: 800M4 Backflow, ea | B29: NEW035 | C29: H | E29: 800M4 Backflow, ea | G29: ea | H29: 0 | I29: 96 | J29: 543 | K29: Y | O29: 45988 | P29: =if(A29='QB Import materials'!A28,0,1) -> 0
A30: Action Fitting, ea | B30: NEW043 | C30: H | E30: Action Fitting, ea | G30: ea | H30: 0 | I30: 3.43 | J30: 6.59 | K30: Y | O30: 45989 | P30: =if(A30='QB Import materials'!A29,0,1) -> 0
A31: Action Manifold, ea | B31: LMN40150675 | C31: H | E31: Action Manifold, ea | G31: ea | H31: 0 | I31: 34.98 | J31: 58.47 | K31: Y | O31: 45989 | P31: =if(A31='QB Import materials'!A30,0,1) -> 0
A32: Alpine Fir, 10', ea | B32: LMN43636215 | C32: H | E32: Alpine Fir, 10', ea | G32: ea | H32: 0 | I32: 751.5 | J32: 1256.14 | O32: 45988 | P32: =if(A32='QB Import materials'!A31,0,1) -> 0
A33: Alpine Fir, 12', ea | B33: LMN43636217 | C33: H | E33: Alpine Fir, 12', ea | G33: ea | H33: 0 | I33: 851.5 | J33: 1423.29 | O33: 45989 | P33: =if(A33='QB Import materials'!A32,0,1) -> 0
A34: Annual Flower Pot, 1 Gal, ea | B34: NEW002 | C34: H | E34: Annual Flower Pot, 1 Gal, ea | G34: ea | H34: 0 | I34: 22 | J34: 22 | K34: Y | O34: 45988 | P34: =if(A34='QB Import materials'!A33,0,1) -> 0
A35: Annual Flower Pot, 1 Qt, ea | B35: NEW003 | C35: H | E35: Annual Flower Pot, 1 Qt, ea | G35: ea | H35: 0 | I35: 15 | J35: 15 | K35: Y | O35: 45988 | P35: =if(A35='QB Import materials'!A34,0,1) -> 0
A36: Annual Flower Pot, 4", ea | B36: NEW004 | C36: H | E36: Annual Flower Pot, 4", ea | G36: ea | H36: 0 | I36: 6 | J36: 6 | K36: Y | O36: 45988 | P36: =if(A36='QB Import materials'!A35,0,1) -> 0
A37: Annual Flowers, miscellaneous, cost | B37: NEW005 | C37: H | E37: Annual Flowers, miscellaneous, cost | G37: $ | H37: 0 | I37: 0 | J37: 1 | O37: 45988 | P37: =if(A37='QB Import materials'!A36,0,1) -> 0
A38: Arbor Tie, ft | B38: LMN40150744 | C38: H | E38: Arbor Tie, ft | G38: ft | H38: 0 | I38: 0.11 | J38: 0.24 | K38: Y | O38: 45988 | P38: =if(A38='QB Import materials'!A37,0,1) -> 0
A39: Aspen, 2.5", Mulit Stem, ea | B39: LMN40150764 | C39: H | E39: Aspen, 2.5", Mulit Stem, ea | G39: ea | H39: 0 | I39: 365 | J39: 637.3 | K39: Y | O39: 45988 | P39: =if(A39='QB Import materials'!A38,0,1) -> 0
A40: Aspen, 2.5", Single Stem, ea | B40: LMN40150758 | C40: H | E40: Aspen, 2.5", Single Stem, ea | G40: ea | H40: 0 | I40: 300 | J40: 532.81 | K40: Y | O40: 45988 | P40: =if(A40='QB Import materials'!A39,0,1) -> 0
...

Sheet QB Import materials
A1: Product/Service Name | B1: Variant Name | C1: Quantity on hand | D1: Item type | E1: Single,parent or variant? | F1: Category | G1: SKU | H1: Price | I1: Cost | J1: Income Account | K1: Expense Account | L1: Inventory asset account | M1: Sales Description | N1: Purchase Description | O1: Reorder Point | P1: Column 1
A2: 1.25" Poly Fitting | D2: Non-inventory | E2: Single | F2: Irrigation Materials | H2: =IF(AND(VLOOKUP(A2,MasterMaterials!A:J,10,FALSE)<>"",VLOOKUP(A2,MasterMaterials!A:J,10,FALSE)<>0),VLOOKUP(A2,MasterMaterials!A:J,10,FALSE),ROUND(I2*1.15/0.688,2)) -> 5.88 | I2: =VLOOKUP(A2,MasterMaterials!A:I,9,FALSE) -> 2.24 | J2: Irrigation Materials | M2: 1.25" Fitting, ea
A3: 1.25" Poly, Ft | D3: Non-inventory | E3: Single | F3: Irrigation Materials | H3: =IF(AND(VLOOKUP(A3,MasterMaterials!A:J,10,FALSE)<>"",VLOOKUP(A3,MasterMaterials!A:J,10,FALSE)<>0),VLOOKUP(A3,MasterMaterials!A:J,10,FALSE),ROUND(I3*1.15/0.688,2)) -> 1.18 | I3: =VLOOKUP(A3,MasterMaterials!A:I,9,FALSE) -> 0.48 | J3: Irrigation Materials | M3: 1.25" Poly, Ft.
A4: 1.25" Stretch Repair Coupling | D4: Non-inventory | E4: Single | F4: Irrigation Materials | H4: =IF(AND(VLOOKUP(A4,MasterMaterials!A:J,10,FALSE)<>"",VLOOKUP(A4,MasterMaterials!A:J,10,FALSE)<>0),VLOOKUP(A4,MasterMaterials!A:J,10,FALSE),ROUND(I4*1.15/0.688,2)) -> 23.83 | I4: =VLOOKUP(A4,MasterMaterials!A:I,9,FALSE) -> 20.72 | J4: Irrigation Materials | M4: 1.25" Stretch Repair Coupling
A5: 1.5" Poly Fitting, ea | D5: Non-inventory | E5: Single | F5: Irrigation Materials | H5: =IF(AND(VLOOKUP(A5,MasterMaterials!A:J,10,FALSE)<>"",VLOOKUP(A5,MasterMaterials!A:J,10,FALSE)<>0),VLOOKUP(A5,MasterMaterials!A:J,10,FALSE),ROUND(I5*1.15/0.688,2)) -> 13.19 | I5: =VLOOKUP(A5,MasterMaterials!A:I,9,FALSE) -> 5.94 | J5: Irrigation Materials | M5: 1.5" Poly Fitting
A6: 1.5" Poly, ft | D6: Non-inventory | E6: Single | F6: Irrigation Materials | H6: =IF(AND(VLOOKUP(A6,MasterMaterials!A:J,10,FALSE)<>"",VLOOKUP(A6,MasterMaterials!A:J,10,FALSE)<>0),VLOOKUP(A6,MasterMaterials!A:J,10,FALSE),ROUND(I6*1.15/0.688,2)) -> 1.87 | I6: =VLOOKUP(A6,MasterMaterials!A:I,9,FALSE) -> 0.87 | J6: Irrigation Materials | M6: 1.5" Poly
A7: 1.5" Stretch Repair Coupling, ea | D7: Non-inventory | E7: Single | F7: Irrigation Materials | H7: =IF(AND(VLOOKUP(A7,MasterMaterials!A:J,10,FALSE)<>"",VLOOKUP(A7,MasterMaterials!A:J,10,FALSE)<>0),VLOOKUP(A7,MasterMaterials!A:J,10,FALSE),ROUND(I7*1.15/0.688,2)) -> 26.22 | I7: =VLOOKUP(A7,MasterMaterials!A:I,9,FALSE) -> 22.8 | J7: Irrigation Materials | M7: 1.5" Stretch Repair Coupling
A8: 1.5" Tie-In Assembly, ea | D8: Non-inventory | E8: Single | F8: Irrigation Materials | H8: =IF(AND(VLOOKUP(A8,MasterMaterials!A:J,10,FALSE)<>"",VLOOKUP(A8,MasterMaterials!A:J,10,FALSE)<>0),VLOOKUP(A8,MasterMaterials!A:J,10,FALSE),ROUND(I8*1.15/0.688,2)) -> 504.99 | I8: =VLOOKUP(A8,MasterMaterials!A:I,9,FALSE) -> 252.5 | J8: Irrigation Materials | M8: 1.5" Tie-In Assembly
A9: 1" Drip Valve, ea | D9: Non-inventory | E9: Single | F9: Irrigation Materials | H9: =IF(AND(VLOOKUP(A9,MasterMaterials!A:J,10,FALSE)<>"",VLOOKUP(A9,MasterMaterials!A:J,10,FALSE)<>0),VLOOKUP(A9,MasterMaterials!A:J,10,FALSE),ROUND(I9*1.15/0.688,2)) -> 97.75 | I9: =VLOOKUP(A9,MasterMaterials!A:I,9,FALSE) -> 50.04 | J9: Irrigation Materials | M9: 1" Drip Valve
A10: 1" Fitting, ea | D10: Non-inventory | E10: Single | F10: Irrigation Materials | H10: =IF(AND(VLOOKUP(A10,MasterMaterials!A:J,10,FALSE)<>"",VLOOKUP(A10,MasterMaterials!A:J,10,FALSE)<>0),VLOOKUP(A10,MasterMaterials!A:J,10,FALSE),ROUND(I10*1.15/0.688,2)) -> 3.6 | I10: =VLOOKUP(A10,MasterMaterials!A:I,9,FALSE) -> 1.62 | J10: Irrigation Materials | M10: 1" Fitting
A11: 1" Poly, ft | D11: Non-inventory | E11: Single | F11: Irrigation Materials | H11: =IF(AND(VLOOKUP(A11,MasterMaterials!A:J,10,FALSE)<>"",VLOOKUP(A11,MasterMaterials!A:J,10,FALSE)<>0),VLOOKUP(A11,MasterMaterials!A:J,10,FALSE),ROUND(I11*1.15/0.688,2)) -> 0.74 | I11: =VLOOKUP(A11,MasterMaterials!A:I,9,FALSE) -> 0.36 | J11: Irrigation Materials | M11: 1" Poly
A12: 1" Stretch Repair Coupling | D12: Non-inventory | E12: Single | F12: Irrigation Materials | H12: =IF(AND(VLOOKUP(A12,MasterMaterials!A:J,10,FALSE)<>"",VLOOKUP(A12,MasterMaterials!A:J,10,FALSE)<>0),VLOOKUP(A12,MasterMaterials!A:J,10,FALSE),ROUND(I12*1.15/0.688,2)) -> 15.74 | I12: =VLOOKUP(A12,MasterMaterials!A:I,9,FALSE) -> 13.69 | J12: Irrigation Materials | M12: 1" Stretch Repair Coupling
A13: 1" Tie-In Assembly, ea | D13: Non-inventory | E13: Single | F13: Irrigation Materials | H13: =IF(AND(VLOOKUP(A13,MasterMaterials!A:J,10,FALSE)<>"",VLOOKUP(A13,MasterMaterials!A:J,10,FALSE)<>0),VLOOKUP(A13,MasterMaterials!A:J,10,FALSE),ROUND(I13*1.15/0.688,2)) -> 204.53 | I13: =VLOOKUP(A13,MasterMaterials!A:I,9,FALSE) -> 128.94 | J13: Irrigation Materials | M13: 1" Tie-In Assembly
... A87: Drip Emitter, ea | D87: Non-inventory | E87: Single | F87: Irrigation Materials | H87: =IF(AND(VLOOKUP(A87,MasterMaterials!A:J,10,FALSE)<>"",VLOOKUP(A87,MasterMaterials!A:J,10,FALSE)<>0),VLOOKUP(A87,MasterMaterials!A:J,10,FALSE),ROUND(I87*1.15/0.688,2)) -> 0.61 | I87: =VLOOKUP(A87,MasterMaterials!A:I,9,FALSE) -> 0.3 | J87: Irrigation Materials | M87: Drip Emitter
A88: Dump Fee Big Sky, ea | D88: Non-inventory | E88: Single | F88: Maintenance | H88: 250 | I88: 250 | J88: Dump | M88: Debris Dump Fee Big Sky, ea
A89: Dump Fee Bozeman, ea | D89: Non-inventory | E89: Single | F89: Maintenance | H89: =IF(AND(VLOOKUP(A89,MasterMaterials!A:J,10,FALSE)<>"",VLOOKUP(A89,MasterMaterials!A:J,10,FALSE)<>0),VLOOKUP(A89,MasterMaterials!A:J,10,FALSE),ROUND(I89*1.15/0.688,2)) -> 55 | I89: =VLOOKUP(A89,MasterMaterials!A:I,9,FALSE) -> 35 | J89: Dump | M89: Debris Dump Fee Bozeman, ea
A90: Edging, Aluminium, ft | D90: Non-inventory | E90: Single | F90: Landscaping Materials | H90: =IF(AND(VLOOKUP(A90,MasterMaterials!A:J,10,FALSE)<>"",VLOOKUP(A90,MasterMaterials!A:J,10,FALSE)<>0),VLOOKUP(A90,MasterMaterials!A:J,10,FALSE),ROUND(I90*1.15/0.688,2)) -> 4.69 | I90: =VLOOKUP(A90,MasterMaterials!A:I,9,FALSE) -> 2.09 | J90: Edging | M90: Edging, Aluminium, ft
A91: Edging, Aluminum Edging Corners, ea | D91: Non-inventory | E91: Single | F91: Landscaping Materials | H91: =IF(AND(VLOOKUP(A91,MasterMaterials!A:J,10,FALSE)<>"",VLOOKUP(A91,MasterMaterials!A:J,10,FALSE)<>0),VLOOKUP(A91,MasterMaterials!A:J,10,FALSE),ROUND(I91*1.15/0.688,2)) -> 20.06 | I91: =VLOOKUP(A91,MasterMaterials!A:I,9,FALSE) -> 12 | J91: Edging | M91: Edging, Aluminum Edging Corners, ea
A92: Edging, Plastic, ea | D92: Non-inventory | E92: Single | F92: Landscaping Materials | H92: =IF(AND(VLOOKUP(A92,MasterMaterials!A:J,10,FALSE)<>"",VLOOKUP(A92,MasterMaterials!A:J,10,FALSE)<>0),VLOOKUP(A92,MasterMaterials!A:J,10,FALSE),ROUND(I92*1.15/0.688,2)) -> 21 | I92: =VLOOKUP(A92,MasterMaterials!A:I,9,FALSE) -> 14.75 | J92: Edging | M92: Edging, Plastic 20', ea
A93: Edging, Steel 5" x 1/4", ft | D93: Non-inventory | E93: Single | F93: Landscaping Materials | H93: =IF(AND(VLOOKUP(A93,MasterMaterials!A:J,10,FALSE)<>"",VLOOKUP(A93,MasterMaterials!A:J,10,FALSE)<>0),VLOOKUP(A93,MasterMaterials!A:J,10,FALSE),ROUND(I93*1.15/0.688,2)) -> 8.42 | I93: =VLOOKUP(A93,MasterMaterials!A:I,9,FALSE) -> 5.04 | J93: Edging | M93: Edging, Steel 5"x1/4", ft
A94: Edging, Steel 5" x 3/16", ft | D94: Non-inventory | E94: Single | F94: Landscaping Materials | H94: =IF(AND(VLOOKUP(A94,MasterMaterials!A:J,10,FALSE)<>"",VLOOKUP(A94,MasterMaterials!A:J,10,FALSE)<>0),VLOOKUP(A94,MasterMaterials!A:J,10,FALSE),ROUND(I94*1.15/0.688,2)) -> 6.8 | I94: =VLOOKUP(A94,MasterMaterials!A:I,9,FALSE) -> 4.07 | J94: Edging | M94: Edging, Steel 5" x 3/16", ft
A95: Erosion Control Blanket, straw, sf | D95: Non-inventory | E95: Single | F95: Landscape Installation | H95: =IF(AND(VLOOKUP(A95,MasterMaterials!A:J,10,FALSE)<>"",VLOOKUP(A95,MasterMaterials!A:J,10,FALSE)<>0),VLOOKUP(A95,MasterMaterials!A:J,10,FALSE),ROUND(I95*1.15/0.688,2)) -> 0.37 | I95: =VLOOKUP(A95,MasterMaterials!A:I,9,FALSE) -> 0.33 | J95: Seeding | M95: Erosion Control Blanket, straw, sf
A96: Fertilizer, Bagged, ea | D96: Non-inventory | E96: Single | F96: Maintenance | H96: =IF(AND(VLOOKUP(A96,MasterMaterials!A:J,10,FALSE)<>"",VLOOKUP(A96,MasterMaterials!A:J,10,FALSE)<>0),VLOOKUP(A96,MasterMaterials!A:J,10,FALSE),ROUND(I96*1.15/0.688,2)) -> 55 | I96: =VLOOKUP(A96,MasterMaterials!A:I,9,FALSE) -> 34.82 | J96: Fertilizer | M96: Fertilizer, Bagged, ea
A97: Fertilizer, Liquid, ea | D97: Non-inventory | E97: Single | F97: Maintenance | H97: =IF(AND(VLOOKUP(A97,MasterMaterials!A:J,10,FALSE)<>"",VLOOKUP(A97,MasterMaterials!A:J,10,FALSE)<>0),VLOOKUP(A97,MasterMaterials!A:J,10,FALSE),ROUND(I97*1.15/0.688,2)) -> 7 | I97: =VLOOKUP(A97,MasterMaterials!A:I,9,FALSE) -> 7 | J97: Fertilizer | M97: Fertilizer, Liquid
A98: Fertilizer, Spikes, ea | D98: Non-inventory | E98: Single | F98: Maintenance | H98: =IF(AND(VLOOKUP(A98,MasterMaterials!A:J,10,FALSE)<>"",VLOOKUP(A98,MasterMaterials!A:J,10,FALSE)<>0),VLOOKUP(A98,MasterMaterials!A:J,10,FALSE),ROUND(I98*1.15/0.688,2)) -> 1.75 | I98: =VLOOKUP(A98,MasterMaterials!A:I,9,FALSE) -> 1.75 | J98: Fertilizer | M98: Fertilizer, Spikes
A99: Filter Fabric, sf | D99: Non-inventory | E99: Single | F99: Landscape Installation | H99: =IF(AND(VLOOKUP(A99,MasterMaterials!A:J,10,FALSE)<>"",VLOOKUP(A99,MasterMaterials!A:J,10,FALSE)<>0),VLOOKUP(A99,MasterMaterials!A:J,10,FALSE),ROUND(I99*1.15/0.688,2)) -> 0.45 | I99: =VLOOKUP(A99,MasterMaterials!A:I,9,FALSE) -> 0.32 | J99: Drainage Materials | M99: Filter Fabric, sf
A100: Flagstone, Dimensional Bluestone, sf | D100: Non-inventory | E100: Single | F100: Landscaping Materials | H100: =IF(AND(VLOOKUP(A100,MasterMaterials!A:J,10,FALSE)<>"",VLOOKUP(A100,MasterMaterials!A:J,10,FALSE)<>0),VLOOKUP(A100,MasterMaterials!A:J,10,FALSE),ROUND(I100*1.15/0.688,2)) -> 20.89 | I100: =VLOOKUP(A100,MasterMaterials!A:I,9,FALSE) -> 12.5 | J100: Hardscape Materials | M100: Flagstone, Dimensional Bluestone, sf
... A122: Mugo Pine, 15 gal/B&B, ea | D122: Non-inventory | E122: Single | F122: Plants | H122: =IF(AND(VLOOKUP(A122,MasterMaterials!A:J,10,FALSE)<>"",VLOOKUP(A122,MasterMaterials!A:J,10,FALSE)<>0),VLOOKUP(A122,MasterMaterials!A:J,10,FALSE),ROUND(I122*1.15/0.688,2)) -> 501.45 | I122: =VLOOKUP(A122,MasterMaterials!A:I,9,FALSE) -> 300 | J122: Shrubs | M122: Mugo Pine, 15 gal/B&B
A123: Mulch Glue, gal | D123: Non-inventory | E123: Single | F123: Maintenance | H123: =IF(AND(VLOOKUP(A123,MasterMaterials!A:J,10,FALSE)<>"",VLOOKUP(A123,MasterMaterials!A:J,10,FALSE)<>0),VLOOKUP(A123,MasterMaterials!A:J,10,FALSE),ROUND(I123*1.15/0.688,2)) -> 48.35 | I123: =VLOOKUP(A123,MasterMaterials!A:I,9,FALSE) -> 38.68 | M123: Mulch Glue, gal
A124: Mulch, Shredded Cedar, Bagged, ea | D124: Non-inventory | E124: Single | F124: Landscape Installation | H124: =IF(AND(VLOOKUP(A124,MasterMaterials!A:J,10,FALSE)<>"",VLOOKUP(A124,MasterMaterials!A:J,10,FALSE)<>0),VLOOKUP(A124,MasterMaterials!A:J,10,FALSE),ROUND(I124*1.15/0.688,2)) -> 10.88 | I124: =VLOOKUP(A124,MasterMaterials!A:I,9,FALSE) -> 5.44 | J124: Mulch | M124: Mulch, Shredded Cedar, Bagged
A125: Mulch, Shredded Cedar, Bulk, yd | D125: Non-inventory | E125: Single | F125: Landscape Installation | H125: =IF(AND(VLOOKUP(A125,MasterMaterials!A:J,10,FALSE)<>"",VLOOKUP(A125,MasterMaterials!A:J,10,FALSE)<>0),VLOOKUP(A125,MasterMaterials!A:J,10,FALSE),ROUND(I125*1.15/0.688,2)) -> 65 | I125: =VLOOKUP(A125,MasterMaterials!A:I,9,FALSE) -> 40.94 | J125: Mulch | M125: Mulch, Shredded Cedar, Bulk
A126: Mulch, Soil Pep, Bagged, ea | D126: Non-inventory | E126: Single | F126: Landscape Installation | H126: =IF(AND(VLOOKUP(A126,MasterMaterials!A:J,10,FALSE)<>"",VLOOKUP(A126,MasterMaterials!A:J,10,FALSE)<>0),VLOOKUP(A126,MasterMaterials!A:J,10,FALSE),ROUND(I126*1.15/0.688,2)) -> 8.84 | I126: =VLOOKUP(A126,MasterMaterials!A:I,9,FALSE) -> 4.42 | J126: Mulch | M126: Mulch, Soil Pep, Bagged
A127: Mulch, Soil Pep, Bulk, yd | D127: Non-inventory | E127: Single | F127: Landscape Installation | H127: =IF(AND(VLOOKUP(A127,MasterMaterials!A:J,10,FALSE)<>"",VLOOKUP(A127,MasterMaterials!A:J,10,FALSE)<>0),VLOOKUP(A127,MasterMaterials!A:J,10,FALSE),ROUND(I127*1.15/0.688,2)) -> 79.12 | I127: =VLOOKUP(A127,MasterMaterials!A:I,9,FALSE) -> 41.21 | J127: Mulch | M127: Mulch, Soil Pep, Bulk
A128: NDS drain box, 12" Includes Grate and Inserts, ea | D128: Non-inventory | E128: Single | F128: Landscaping Materials | H128: =IF(AND(VLOOKUP(A128,MasterMaterials!A:J,10,FALSE)<>"",VLOOKUP(A128,MasterMaterials!A:J,10,FALSE)<>0),VLOOKUP(A128,MasterMaterials!A:J,10,FALSE),ROUND(I128*1.15/0.688,2)) -> 142.93 | I128: =VLOOKUP(A128,MasterMaterials!A:I,9,FALSE) -> 85.51 | J128: Drainage Materials | M128: NDS drain box, 12" Includes Grate and Inserts
A129: NDS Drain Box, 9" Includes Grate and Inserts, ea | D129: Non-inventory | E129: Single | F129: Landscaping Materials | H129: =IF(AND(VLOOKUP(A129,MasterMaterials!A:J,10,FALSE)<>"",VLOOKUP(A129,MasterMaterials!A:J,10,FALSE)<>0),VLOOKUP(A129,MasterMaterials!A:J,10,FALSE),ROUND(I129*1.15/0.688,2)) -> 99.2 | I129: =VLOOKUP(A129,MasterMaterials!A:I,9,FALSE) -> 59.35 | J129: Drainage Materials | M129: NDS Drain Box, 9" Includes Grate and Inserts
A130: Neem Oil, bottle, ea | D130: Non-inventory | E130: Single | F130: Maintenance | H130: =IF(AND(VLOOKUP(A130,MasterMaterials!A:J,10,FALSE)<>"",VLOOKUP(A130,MasterMaterials!A:J,10,FALSE)<>0),VLOOKUP(A130,MasterMaterials!A:J,10,FALSE),ROUND(I130*1.15/0.688,2)) -> 52.5 | I130: =VLOOKUP(A130,MasterMaterials!A:I,9,FALSE) -> 42 | J130: Herbicide | M130: Neem Oil, bottle
A131: Netafim, ft | D131: Non-inventory | E131: Single | F131: Irrigation Materials | H131: =IF(AND(VLOOKUP(A131,MasterMaterials!A:J,10,FALSE)<>"",VLOOKUP(A131,MasterMaterials!A:J,10,FALSE)<>0),VLOOKUP(A131,MasterMaterials!A:J,10,FALSE),ROUND(I131*1.15/0.688,2)) -> 0.74 | I131: =VLOOKUP(A131,MasterMaterials!A:I,9,FALSE) -> 0.32 | J131: Irrigation Materials | M131: Netafim
A132: Node, 1 Station, ea | D132: Non-inventory | E132: Single | F132: Irrigation Materials | H132: =IF(AND(VLOOKUP(A132,MasterMaterials!A:J,10,FALSE)<>"",VLOOKUP(A132,MasterMaterials!A:J,10,FALSE)<>0),VLOOKUP(A132,MasterMaterials!A:J,10,FALSE),ROUND(I132*1.15/0.688,2)) -> 233.01 | I132: =VLOOKUP(A132,MasterMaterials!A:I,9,FALSE) -> 111.02 | J132: Irrigation Materials | M132: Node, 1 Station
A133: Node, 2 Station, ea | D133: Non-inventory | E133: Single | F133: Irrigation Materials | H133: =IF(AND(VLOOKUP(A133,MasterMaterials!A:J,10,FALSE)<>"",VLOOKUP(A133,MasterMaterials!A:J,10,FALSE)<>0),VLOOKUP(A133,MasterMaterials!A:J,10,FALSE),ROUND(I133*1.15/0.688,2)) -> 357.21 | I133: =VLOOKUP(A133,MasterMaterials!A:I,9,FALSE) -> 152.4 | J133: Irrigation Materials | M133: Node, 2 Station
A134: Noxious weed control, hr | D134: Non-inventory | E134: Single | F134: Maintenance | H134: =IF(AND(VLOOKUP(A134,MasterMaterials!A:J,10,FALSE)<>"",VLOOKUP(A134,MasterMaterials!A:J,10,FALSE)<>0),VLOOKUP(A134,MasterMaterials!A:J,10,FALSE),ROUND(I134*1.15/0.688,2)) -> 82 | I134: =VLOOKUP(A134,MasterMaterials!A:I,9,FALSE) -> 81 | J134: Herbicide | M134: Noxious weed control
...

Sheet LMN Import Materials
A1: =MasterMaterials!A2 -> Name | B1: =MasterMaterials!B2 -> ID | C1: =MasterMaterials!C2 -> Type | D1: =MasterMaterials!D2 -> Size | E1: =MasterMaterials!E2 -> Description | F1: =MasterMaterials!F2 -> Internal | G1: =MasterMaterials!G2 -> Units | H1: =MasterMaterials!H2 -> Round | ... O1: =MasterMaterials!O2 -> LastEditDate | Q1: =MasterMaterials!Q2 | R1: =MasterMaterials!R2
A2: =MasterMaterials!A3 -> 1.25" Poly Fitting | B2: =MasterMaterials!B3 -> NEW048 | C2: =MasterMaterials!C3 | D2: =MasterMaterials!D3 | E2: =MasterMaterials!E3 -> 1.25" Fitting, ea | F2: =MasterMaterials!F3 | G2: =MasterMaterials!G3 -> ea | H2: =MasterMaterials!H3 -> 0 | ... O2: =MasterMaterials!O3
A3: =MasterMaterials!A4 -> 1.25" Poly, Ft | B3: =MasterMaterials!B4 -> NEW047 | C3: =MasterMaterials!C4 | D3: =MasterMaterials!D4 | E3: =MasterMaterials!E4 -> 1.25" Poly, Ft. | F3: =MasterMaterials!F4 | G3: =MasterMaterials!G4 -> ft | H3: =MasterMaterials!H4 -> 0 | ... O3: =MasterMaterials!O4
A4: =MasterMaterials!A5 -> 1.25" Stretch Repair Coupling | B4: =MasterMaterials!B5 -> LMN42485636 | C4: =MasterMaterials!C5 -> H | D4: =MasterMaterials!D5 | E4: =MasterMaterials!E5 -> 1.25" Stretch Repair Coupling | F4: =MasterMaterials!F5 | G4: =MasterMaterials!G5 -> ea | H4: =MasterMaterials!H5 -> 0 | ... O4: =MasterMaterials!O5 -> 45518
A5: =MasterMaterials!A6 -> 1.5" Poly Fitting, ea | B5: =MasterMaterials!B6 -> LMN40150704 | C5: =MasterMaterials!C6 -> H | D5: =MasterMaterials!D6 | E5: =MasterMaterials!E6 -> 1.5" Poly Fitting, ea | F5: =MasterMaterials!F6 | G5: =MasterMaterials!G6 -> ea | H5: =MasterMaterials!H6 -> 0 | ... O5: =MasterMaterials!O6 -> 45988
A6: =MasterMaterials!A7 -> 1.5" Poly, ft | B6: =MasterMaterials!B7 -> LMN40150705 | C6: =MasterMaterials!C7 -> H | D6: =MasterMaterials!D7 | E6: =MasterMaterials!E7 -> 1.5" Poly, ft | F6: =MasterMaterials!F7 | G6: =MasterMaterials!G7 -> ft | H6: =MasterMaterials!H7 -> 0 | ... O6: =MasterMaterials!O7 -> 45988
A7: =MasterMaterials!A8 -> 1.5" Stretch Repair Coupling, ea | B7: =MasterMaterials!B8 -> LMN42486243 | C7: =MasterMaterials!C8 -> H | D7: =MasterMaterials!D8 | E7: =MasterMaterials!E8 -> 1.5" Stretch Repair Coupling, ea | F7: =MasterMaterials!F8 | G7: =MasterMaterials!G8 -> ea | H7: =MasterMaterials!H8 -> 0 | ... O7: =MasterMaterials!O8 -> 45988
A8: =MasterMaterials!A9 -> 1.5" Tie-In Assembly, ea | B8: =MasterMaterials!B9 -> LMN40150680 | C8: =MasterMaterials!C9 -> H | D8: =MasterMaterials!D9 | E8: =MasterMaterials!E9 -> 1.5" Tie-In Assembly, ea | F8: =MasterMaterials!F9 | G8: =MasterMaterials!G9 -> ea | H8: =MasterMaterials!H9 -> 0 | ... O8: =MasterMaterials!O9 -> 45988
A9: =MasterMaterials!A10 -> 1" Drip Valve, ea | B9: =MasterMaterials!B10 -> LMN40150676 | C9: =MasterMaterials!C10 -> H | D9: =MasterMaterials!D10 | E9: =MasterMaterials!E10 -> 1" Drip Valve, ea | F9: =MasterMaterials!F10 | G9: =MasterMaterials!G10 -> ea | H9: =MasterMaterials!H10 -> 0 | ... O9: =MasterMaterials!O10 -> 45988
A10: =MasterMaterials!A11 -> 1" Fitting, ea | B10: =MasterMaterials!B11 -> LMN40150670 | C10: =MasterMaterials!C11 -> H | D10: =MasterMaterials!D11 | E10: =MasterMaterials!E11 -> 1" Fitting, ea | F10: =MasterMaterials!F11 | G10: =MasterMaterials!G11 -> ea | H10: =MasterMaterials!H11 -> 0 | ... O10: =MasterMaterials!O11 -> 45988
A11: =MasterMaterials!A12 -> 1" Poly, ft | B11: =MasterMaterials!B12 -> LMN40150667 | C11: =MasterMaterials!C12 -> H | D11: =MasterMaterials!D12 | E11: =MasterMaterials!E12 -> 1" Poly, ft | F11: =MasterMaterials!F12 | G11: =MasterMaterials!G12 -> ft | H11: =MasterMaterials!H12 -> 0 | ... O11: =MasterMaterials!O12 -> 45988
A12: =MasterMaterials!A13 -> 1" Stretch Repair Coupling | B12: =MasterMaterials!B13 -> LMN42485635 | C12: =MasterMaterials!C13 -> H | D12: =MasterMaterials!D13 | E12: =MasterMaterials!E13 -> 1" Stretch Repair Coupling | F12: =MasterMaterials!F13 | G12: =MasterMaterials!G13 -> ea | H12: =MasterMaterials!H13 -> 0 | ... O12: =MasterMaterials!O13 -> 45518
A13: =MasterMaterials!A14 -> 1" Tie-In Assembly, ea | B13: =MasterMaterials!B14 -> LMN40150679 | C13: =MasterMaterials!C14 -> H | D13: =MasterMaterials!D14 | E13: =MasterMaterials!E14 -> 1" Tie-In Assembly, ea | F13: =MasterMaterials!F14 | G13: =MasterMaterials!G14 -> ea | H13: =MasterMaterials!H14 -> 0 | ... O13: =MasterMaterials!O14 -> 45988
... A79: =MasterMaterials!A80 -> Delivery (Install), Bozeman, ea | B79: =MasterMaterials!B80 -> NEW010 | C79: =MasterMaterials!C80 -> H | D79: =MasterMaterials!D80 | E79: =MasterMaterials!E80 -> Delivery, Bozeman, ea | F79: =MasterMaterials!F80 | G79: =MasterMaterials!G80 -> ea | H79: =MasterMaterials!H80 -> 0 | ... O79: =MasterMaterials!O80 -> 45988
A80: =MasterMaterials!A83 -> Douglas Fir, 10', ea | B80: =MasterMaterials!B83 -> LMN44279462 | C80: =MasterMaterials!C83 -> H | D80: =MasterMaterials!D83 | E80: =MasterMaterials!E83 -> Douglas Fir, 10', ea | F80: =MasterMaterials!F83 | G80: =MasterMaterials!G83 -> ea | H80: =MasterMaterials!H83 -> 0 | ... O80: =MasterMaterials!O83 -> 45988
A81: =MasterMaterials!A84 -> Douglas Fir, 6', ea | B81: =MasterMaterials!B84 -> LMN44279620 | C81: =MasterMaterials!C84 -> H | D81: =MasterMaterials!D84 | E81: =MasterMaterials!E84 -> Douglas Fir, 6', ea | F81: =MasterMaterials!F84 | G81: =MasterMaterials!G84 -> ea | H81: =MasterMaterials!H84 -> 0 | ... O81: =MasterMaterials!O84 -> 45988
A82: =MasterMaterials!A85 -> Douglas Fir, 7', ea | B82: =MasterMaterials!B85 -> LMN44279617 | C82: =MasterMaterials!C85 -> H | D82: =MasterMaterials!D85 | E82: =MasterMaterials!E85 -> Douglas Fir, 7', ea | F82: =MasterMaterials!F85 | G82: =MasterMaterials!G85 -> ea | H82: =MasterMaterials!H85 -> 0 | ... O82: =MasterMaterials!O85 -> 45988
A83: =MasterMaterials!A86 -> Douglas Fir, 8', ea | B83: =MasterMaterials!B86 -> LMN44279455 | C83: =MasterMaterials!C86 -> H | D83: =MasterMaterials!D86 | E83: =MasterMaterials!E86 -> Douglas Fir, 8', ea | F83: =MasterMaterials!F86 | G83: =MasterMaterials!G86 -> ea | H83: =MasterMaterials!H86 -> 0 | ... O83: =MasterMaterials!O86 -> 45988
A84: =MasterMaterials!A87 -> Douglas Fir, 9', ea | B84: =MasterMaterials!B87 -> LMN44279460 | C84: =MasterMaterials!C87 -> H | D84: =MasterMaterials!D87 | E84: =MasterMaterials!E87 -> Douglas Fir, 9', ea | F84: =MasterMaterials!F87 | G84: =MasterMaterials!G87 -> ea | H84: =MasterMaterials!H87 -> 0 | ... O84: =MasterMaterials!O87 -> 45988
A85: =MasterMaterials!A88 -> Drip Emitter, ea | B85: =MasterMaterials!B88 -> LMN40150668 | C85: =MasterMaterials!C88 -> H | D85: =MasterMaterials!D88 | E85: =MasterMaterials!E88 -> Drip Emitter, ea | F85: =MasterMaterials!F88 | G85: =MasterMaterials!G88 -> ea | H85: =MasterMaterials!H88 -> 0 | ... O85: =MasterMaterials!O88 -> 45989
A86: =MasterMaterials!A89 -> Dump Fee Big Sky, ea | B86: =MasterMaterials!B89 -> LMN49034492 | C86: =MasterMaterials!C89 | D86: =MasterMaterials!D89 | E86: =MasterMaterials!E89 -> Debris Dump Fee Big Sky, ea | F86: =MasterMaterials!F89 | G86: =MasterMaterials!G89 -> ea | H86: =MasterMaterials!H89 | ... O86: =MasterMaterials!O89
A87: =MasterMaterials!A90 -> Dump Fee Bozeman, ea | B87: =MasterMaterials!B90 -> NEW011 | C87: =MasterMaterials!C90 -> H | D87: =MasterMaterials!D90 | E87: =MasterMaterials!E90 -> Debris Dump Fee Bozeman, ea | F87: =MasterMaterials!F90 | G87: =MasterMaterials!G90 -> ea | H87: =MasterMaterials!H90 -> 0 | ... O87: =MasterMaterials!O90 -> 45988
A88: =MasterMaterials!A91 -> Edging, Aluminium, ft | B88: =MasterMaterials!B91 -> LMN40150742 | C88: =MasterMaterials!C91 -> H | D88: =MasterMaterials!D91 | E88: =MasterMaterials!E91 -> Edging, Aluminium, ft | F88: =MasterMaterials!F91 | G88: =MasterMaterials!G91 -> ft | H88: =MasterMaterials!H91 -> 0 | ... O88: =MasterMaterials!O91 -> 45989
A89: =MasterMaterials!A92 -> Edging, Aluminum Edging Corners, ea | B89: =MasterMaterials!B92 -> LMN45549103 | C89: =MasterMaterials!C92 -> H | D89: =MasterMaterials!D92 | E89: =MasterMaterials!E92 -> Aluminum Edging Corners, ea | F89: =MasterMaterials!F92 | G89: =MasterMaterials!G92 -> ea | H89: =MasterMaterials!H92 -> 0 | ... O89: =MasterMaterials!O92 -> 45988
A90: =MasterMaterials!A93 -> Edging, Plastic, ea | B90: =MasterMaterials!B93 -> NEW012 | C90: =MasterMaterials!C93 -> H | D90: =MasterMaterials!D93 | E90: =MasterMaterials!E93 -> Edging, Plastic, ea | F90: =MasterMaterials!F93 | G90: =MasterMaterials!G93 -> ea | H90: =MasterMaterials!H93 -> 0 | ... O90: =MasterMaterials!O93 -> 45989
A91: =MasterMaterials!A94 -> Edging, Steel 5" x 1/4", ft | B91: =MasterMaterials!B94 -> LMN40150741 | C91: =MasterMaterials!C94 -> H | D91: =MasterMaterials!D94 | E91: =MasterMaterials!E94 -> Edging, Steel 5" x 1/4", ft | F91: =MasterMaterials!F94 | G91: =MasterMaterials!G94 -> ft | H91: =MasterMaterials!H94 -> 0 | ... O91: =MasterMaterials!O94 -> 45988
... A120: =MasterMaterials!A123 -> Mugo Pine, 15 gal/B&B, ea | B120: =MasterMaterials!B123 -> LMN40150772 | C120: =MasterMaterials!C123 -> H | D120: =MasterMaterials!D123 | E120: =MasterMaterials!E123 -> Mugo Pine, 15 gal/B&B, ea | F120: =MasterMaterials!F123 | G120: =MasterMaterials!G123 -> ea | H120: =MasterMaterials!H123 -> 0 | ... O120: =MasterMaterials!O123 -> 45988
A121: =MasterMaterials!A125 -> Mulch, Shredded Cedar, Bagged, ea | B121: =MasterMaterials!B125 -> LMN40150721 | C121: =MasterMaterials!C125 -> H | D121: =MasterMaterials!D125 | E121: =MasterMaterials!E125 -> Mulch, Shredded Cedar, Bagged, ea | F121: =MasterMaterials!F125 | G121: =MasterMaterials!G125 -> ea | H121: =MasterMaterials!H125 -> 0 | ... O121: =MasterMaterials!O125 -> 46129
A122: =MasterMaterials!A126 -> Mulch, Shredded Cedar, Bulk, yd | B122: =MasterMaterials!B126 -> LMN40150716 | C122: =MasterMaterials!C126 -> H | D122: =MasterMaterials!D126 | E122: =MasterMaterials!E126 -> Mulch, Shredded Cedar, Bulk, yd | F122: =MasterMaterials!F126 | G122: =MasterMaterials!G126 -> yd | H122: =MasterMaterials!H126 -> 0 | ... O122: =MasterMaterials!O126 -> 45989
A123: =MasterMaterials!A127 -> Mulch, Soil Pep, Bagged, ea | B123: =MasterMaterials!B127 -> LMN40150717 | C123: =MasterMaterials!C127 -> H | D123: =MasterMaterials!D127 | E123: =MasterMaterials!E127 -> Mulch, Soil Pep, Bagged, ea | F123: =MasterMaterials!F127 | G123: =MasterMaterials!G127 -> ea | H123: =MasterMaterials!H127 -> 0 | ... O123: =MasterMaterials!O127 -> 46129
A124: =MasterMaterials!A128 -> Mulch, Soil Pep, Bulk, yd | B124: =MasterMaterials!B128 -> LMN40150722 | C124: =MasterMaterials!C128 -> H | D124: =MasterMaterials!D128 | E124: =MasterMaterials!E128 -> Mulch, Soil Pep, Bulk, yd | F124: =MasterMaterials!F128 | G124: =MasterMaterials!G128 -> yd | H124: =MasterMaterials!H128 -> 0 | ... O124: =MasterMaterials!O128 -> 45989
A125: =MasterMaterials!A129 -> NDS drain box, 12" Includes Grate and Inserts, ea | B125: =MasterMaterials!B129 -> LMN40150735 | C125: =MasterMaterials!C129 -> H | D125: =MasterMaterials!D129 | E125: =MasterMaterials!E129 -> NDS drain box, 12" Includes Grate and Inserts, ea | F125: =MasterMaterials!F129 | G125: =MasterMaterials!G129 -> ea | H125: =MasterMaterials!H129 -> 0 | ... O125: =MasterMaterials!O129 -> 45988
A126: =MasterMaterials!A130 -> NDS Drain Box, 9" Includes Grate and Inserts, ea | B126: =MasterMaterials!B130 -> LMN40150734 | C126: =MasterMaterials!C130 -> H | D126: =MasterMaterials!D130 | E126: =MasterMaterials!E130 -> NDS Drain Box, 9" Includes Grate and Inserts, ea | F126: =MasterMaterials!F130 | G126: =MasterMaterials!G130 -> ea | H126: =MasterMaterials!H130 -> 0 | ... O126: =MasterMaterials!O130 -> 45988
A127: =MasterMaterials!A131 -> Neem Oil, bottle, ea | B127: =MasterMaterials!B131 -> NEW020 | C127: =MasterMaterials!C131 -> H | D127: =MasterMaterials!D131 | E127: =MasterMaterials!E131 -> Neem Oil, bottle, ea | F127: =MasterMaterials!F131 | G127: =MasterMaterials!G131 -> ea | H127: =MasterMaterials!H131 -> 0 | ... O127: =MasterMaterials!O131 -> 46129
A128: =MasterMaterials!A132 -> Netafim, ft | B128: =MasterMaterials!B132 -> LMN40150664 | C128: =MasterMaterials!C132 -> H | D128: =MasterMaterials!D132 | E128: =MasterMaterials!E132 -> Netafim, ft | F128: =MasterMaterials!F132 | G128: =MasterMaterials!G132 -> ft | H128: =MasterMaterials!H132 -> 0 | ... O128: =MasterMaterials!O132 -> 45989
A129: =MasterMaterials!A133 -> Node, 1 Station, ea | B129: =MasterMaterials!B133 -> LMN40150690 | C129: =MasterMaterials!C133 -> H | D129: =MasterMaterials!D133 | E129: =MasterMaterials!E133 -> Node, 1 Station, ea | F129: =MasterMaterials!F133 | G129: =MasterMaterials!G133 -> ea | H129: =MasterMaterials!H133 -> 0 | ... O129: =MasterMaterials!O133 -> 45988
A130: =MasterMaterials!A134 -> Node, 2 Station, ea | B130: =MasterMaterials!B134 -> NEW037 | C130: =MasterMaterials!C134 -> H | D130: =MasterMaterials!D134 | E130: =MasterMaterials!E134 -> Node, 2 Station, ea | F130: =MasterMaterials!F134 | G130: =MasterMaterials!G134 -> ea | H130: =MasterMaterials!H134 -> 0 | ... O130: =MasterMaterials!O134 -> 45988
A131: =MasterMaterials!A135 -> Noxious weed control, hr | B131: =MasterMaterials!B135 -> NEW021 | C131: =MasterMaterials!C135 -> H | D131: =MasterMaterials!D135 | E131: =MasterMaterials!E135 -> Noxious weed control, hr | F131: =MasterMaterials!F135 | G131: =MasterMaterials!G135 -> hr | H131: =MasterMaterials!H135 -> 0 | ... O131: =MasterMaterials!O135 -> 45988
A132: =MasterMaterials!A136 -> Nozzle, MP Rotator, ea | B132: =MasterMaterials!B136 -> LMN40150687 | C132: =MasterMaterials!C136 -> H | D132: =MasterMaterials!D136 | E132: =MasterMaterials!E136 -> Nozzle, MP Rotator, ea | F132: =MasterMaterials!F136 | G132: =MasterMaterials!G136 -> ea | H132: =MasterMaterials!H136 -> 0 | ... O132: =MasterMaterials!O136 -> 45988
A133: =MasterMaterials!A137 -> Nozzle, RVAN, ea | B133: =MasterMaterials!B137 -> NEW038 | C133: =MasterMaterials!C137 -> H | D133: =MasterMaterials!D137 | E133: =MasterMaterials!E137 -> Nozzle, RVAN, ea | F133: =MasterMaterials!F137 | G133: =MasterMaterials!G137 -> ea | H133: =MasterMaterials!H137 -> 0 | ... O133: =MasterMaterials!O137 -> 45989
...

Sheet QB Import Equipment and Labor
A1: Product/Service Name | B1: Variant Name | C1: Quantity on hand | D1: Item type | E1: Single,parent or variant? | F1: Category | G1: SKU | H1: Option 1 name | I1: Option 1 value | J1: Option 2 name | K1: Option 2 value | L1: Option 3 name | M1: Option 3 value | N1: Option 4 name | O1: Option 4 value | P1: Option 5 name | Q1: Option 5 value | R1: Price | S1: Cost | T1: Income Account | U1: Expense Account | V1: Inventory asset account | W1: Sales Description | X1: Purchase Description | Y1: Reorder Point
A2: Install Hourly labor | D2: Service | E2: Single | F2: Labor | R2: 89 | S2: 30.75 | T2: Labor | W2: Install Hourly labor
A3: Irrigation Service Call, hourly-BS | D3: Service | E3: Single | F3: Labor | R3: 250 | S3: 0 | T3: Labor | W3: Irrigation Service Call, hourly-BS
A4: Irrigation Service Call, hourly-Bzn | D4: Service | E4: Single | F4: Labor | R4: 150 | S4: 0 | T4: Labor | W4: Irrigation Service Call, hourly-Bzn
A5: Irrigation Techinician Hourly labor | D5: Service | E5: Single | F5: Labor | R5: 125 | S5: 60.72 | T5: Labor | W5: Irrigation Techinician Hourly labor
A6: Irrigation Technician Hourly Labor | D6: Service | E6: Single | F6: Labor | R6: 95 | S6: 0 | T6: Labor | W6: Irrigation Technician Hourly Labor
A7: Maintenance Hourly Labor - BIG SKY | D7: Service | E7: Single | F7: Labor | R7: 79 | S7: 0 | T7: Labor | W7: Maintenance Hourly Labor - BIG SKY
A8: Maintenance Hourly Labor - TOWN | D8: Service | E8: Single | F8: Labor | R8: 75 | S8: 31.34 | T8: Labor | W8: Maintenance Hourly Labor - TOWN
A9: Mow Hourly Rate - BIG SKY | D9: Service | E9: Single | F9: Labor | R9: 150 | S9: 0 | T9: Labor | W9: Mow Hourly Rate - BIG SKY
A10: Mow Hourly Rate - TOWN | D10: Service | E10: Single | F10: Labor | R10: 95 | S10: 0 | T10: Labor | W10: Mow Hourly Rate - TOWN
A11: Winterization-Bzn | D11: Service | E11: Single | F11: Labor | R11: 195 | S11: 0 | T11: Labor | W11: Winterization-Bzn
A12: Amp Conveyor Rental/ Week | D12: Service | E12: Single | F12: Equipment | R12: 1080 | S12: 900 | T12: Equipment | W12: Amp Conveyor Rental/ Week
A13: AMP Shooter Truck, hourly | D13: Service | E13: Single | F13: Equipment | R13: 240 | S13: 200 | T13: Equipment | W13: AMP Shooter Truck
... A38: Welding Kit Daily Fee | D38: Service | E38: Single | F38: Equipment | R38: 140 | S38: 6.05 | T38: Equipment | W38: Welding Kit Daily Fee

Sheet Irrigation Bundles 2026
A1: Item | B1: Part Number (Cell B) | C1: Quantity (Cell C) | D1: Unit Price (Cell D) | E1: Calculated Cost (Cell E)
A2: **1'' Poly Repair Bundle** | E2: 11.24
A3: 1" Fitting, ea | B3: LMN40150670 | C3: 2 | D3: 3.6 | E3: 7.2
A4: Crimp Rings, ea | B4: NEW044 | C4: 8 | D4: 0.32 | E4: 2.56
A5: Ft 1'' Poly | B5: LMN40150667 | C5: 2 | D5: 0.74 | E5: 1.48
A6: **1.25" Poly Repair Bundle** | E6: 6.92
A7: 1.25" Fittings | B7: LMN40150665 | C7: 2 | D7: 1.69 | E7: 3.38
A8: 1.25" Crimp Rings | B8: NEW044 | C8: 8 | D8: 0.32 | E8: 2.56
A9: Ft 1.25" Poly | B9: LMN40150666 | C9: 2 | D9: 0.49 | E9: 0.98
A10: **1.5" Poly Repair Bundle** | E10: 32.68
A11: 1.5" Fittings | B11: LMN40150704 | C11: 2 | D11: 13.19 | E11: 26.38
A12: 1.5" Crimp Rings | B12: NEW044 | C12: 8 | D12: 0.32 | E12: 2.56
A13: Ft 1.5" Poly | B13: LMN40150705 | C13: 2 | D13: 1.87 | E13: 3.74
A14: **Wire splice bundle (7 Strand)** | E14: 48.17
A15: Snap Locks | B15: LMN40150701 | C15: 14 | D15: 2.61 | E15: 36.54
A16: Ft. 7 strand wire | B16: NEW053 | C16: 2 | D16: 1 | E16: 2
A17: 6" Round Valve box | B17: NEW051 | C17: 1 | D17: 9.63 | E17: 9.63
A18: **Wire Splice Bundle (10 Strand)** | E18: 64.95
A19: Snap Locks | B19: LMN40150701 | C19: 20 | D19: 2.61 | E19: 52.2
A20: Ft. 10 Strand wire | B20: LMN40150698 | C20: 2 | D20: 1.56 | E20: 3.12
A21: 6" Round Valve box | B21: NEW051 | C21: 1 | D21: 9.63 | E21: 9.63
A22: **Wire Splice Bundle ( 13 Strand)** | E22: 81.17
A23: Snap Locks | B23: LMN40150701 | C23: 26 | D23: 2.61 | E23: 67.86
A24: Ft. 13 Strand wire | B24: NEW054 | C24: 2 | D24: 1.84 | E24: 3.68
A25: 6" Round Valve Box | B25: NEW051 | C25: 1 | D25: 9.63 | E25: 9.63

Sheet MasterMaint Prices
A1: PLEASE DELETE | C1: DO NOT USE
A2: Name | B2: ID | C2: Type | D2: Size | E2: Description | F2: Internal | G2: Units | H2: Round | I2: Cost | J2: Price | K2: FixedPrice | L2: Profit | M2: Ship | N2: Warranty | O2: LastEditDate
A3: 1/2" Poly, ft | B3: LMN40150666 | C3: H | E3: 1/2" Poly, ft | G3: ft | H3: 0 | I3: 0.49 | J3: 0.49 | K3: Y | O3: 45989
A4: Annual Flower Pot, 1 Gal, ea | B4: NEW002 | C4: H | E4: Annual Flower Pot, 1 Gal, ea | G4: ea | H4: 0 | I4: 22 | J4: 22 | K4: Y | O4: 45988
A5: Annual Flower Pot, 1 Qt, ea | B5: NEW003 | C5: H | E5: Annual Flower Pot, 1 Qt, ea | G5: ea | H5: 0 | I5: 15 | J5: 15 | K5: Y | O5: 45988
A6: Annual Flower Pot, 4", ea | B6: NEW004 | C6: H | E6: Annual Flower Pot, 4", ea | G6: ea | H6: 0 | I6: 6 | J6: 6 | K6: Y | O6: 45988
A7: Annual Flowers, miscellaneous, ea | B7: NEW005 | C7: H | E7: Annual Flowers, miscellaneous, ea | G7: ea | H7: 0 | I7: 0 | O7: 45988
A8: Bulb, ea | B8: LMN40150788 | C8: H | E8: Bulb, ea | G8: ea | H8: 0 | I8: 1.4 | O8: 45988
A9: Bulk, misc | B9: LMN43171760 | C9: H | G9: $ | H9: 0 | I9: 1 | O9: 45958
A10: Caging, linear, ft | B10: NEW006 | C10: H | E10: Caging, linear, ft | G10: ft | H10: 0 | I10: 2.58 | J10: 2.58 | K10: Y | O10: 45988
A11: Compost, Bagged, ea | B11: LMN40150720 | C11: H | E11: Compost, Bagged, ea | G11: ea | H11: 0 | I11: 9.95 | J11: 9.95 | K11: Y | O11: 45989
A12: Compost, Bulk, yd | B12: LMN40150719 | C12: H | E12: Compost, Bulk, yd | G12: yd | H12: 0 | I12: 59 | J12: 59 | K12: Y | O12: 45989
A13: Deer Spray, Big Sky, ea | B13: NEW007 | C13: H | E13: Deer Spray, Big Sky, ea | G13: ea | H13: 0 | I13: 15 | J13: 15 | K13: Y | O13: 45988
A14: Deer Spray, Bozeman, ea | B14: NEW008 | C14: H | E14: Deer Spray, Bozeman, ea | G14: ea | H14: 0 | I14: 10 | J14: 10 | K14: Y | O14: 45988
A15: Delivery, Big Sky, ea | B15: NEW009 | C15: H | E15: Delivery, Big Sky, ea | G15: ea | H15: 0 | I15: 250 | J15: 250 | K15: Y | O15: 45988
A16: Delivery, Bozeman, ea | B16: NEW010 | C16: H | E16: Delivery, Bozeman, ea | G16: ea | H16: 0 | I16: 85 | J16: 85 | K16: Y | O16: 45988
A17: Drip Emitter, ea | B17: LMN40150668 | C17: H | E17: Drip Emitter, ea | G17: ea | H17: 0 | I17: 50 | O17: 45989
A18: Dump fee, ea | B18: NEW011 | C18: H | E18: Dump fee, ea | G18: ea | H18: 0 | I18: 55 | J18: 55 | K18: Y | O18: 45988
A19: Edging, Aluminium, ft | B19: LMN40150742 | C19: H | E19: Edging, Aluminium, ft | G19: ft | H19: 0 | I19: 7.5 | L19: 0.31 | O19: 45989
A20: Edging, Plastic, ea | B20: NEW012 | C20: H | E20: Edging, Plastic, ea | G20: ea | H20: 0 | I20: 55 | J20: 55 | K20: Y | O20: 45989
A21: Erosion Control Blanket, straw, sf | B21: LMN40150795 | C21: H | E21: Erosion Control Blanket, straw, sf | G21: sf | H21: 0 | I21: 0.33 | O21: 45989
A22: Fertilizer, Bagged, ea | B22: LMN40150793 | C22: H | E22: Fertilizer, Bagged, ea | G22: ea | H22: 0 | I22: 55 | J22: 55 | K22: Y | O22: 45989
A23: Fertilizer, Liquid, ea | B23: NEW013 | C23: H | E23: Fertilizer, Liquid, ea | G23: ea | H23: 0 | I23: 7 | J23: 7 | K23: Y | O23: 45988
A24: Fertilizer, Spikes, ea | B24: NEW014 | C24: H | E24: Fertilizer, Spikes, ea | G24: ea | H24: 0 | I24: 1.75 | J24: 1.75 | K24: Y | O24: 45988
A25: Insecticidal Soap, ea | B25: NEW015 | C25: H | E25: Insecticidal Soap, ea | G25: ea | H25: 0 | I25: 19.95 | J25: 19.95 | K25: Y | O25: 45988
A26: Lawn Service, ea | B26: NEW017 | C26: H | E26: Lawn Service, ea | G26: ea | H26: 0 | I26: 150 | J26: 150 | K26: Y | O26: 45988
A27: Mileage, ea | B27: LMN42434662 | C27: H | E27: Mileage, ea | G27: ea | H27: 0 | I27: 2.5 | J27: 2.5 | K27: Y | O27: 45989
A28: Mulch, Shredded Cedar, Bagged, ea | B28: LMN40150721 | C28: H | E28: Mulch, Shredded Cedar, Bagged, ea | G28: ea | H28: 0 | I28: 8.66 | O28: 45989
A29: Mulch, Shredded Cedar, Bulk, yd | B29: LMN40150716 | C29: H | E29: Mulch, Shredded Cedar, Bulk, yd | G29: yd | H29: 0 | I29: 65 | J29: 65 | K29: Y | O29: 45989
A30: Mulch, Soil Pep, Bagged, ea | B30: LMN40150717 | C30: H | E30: Mulch, Soil Pep, Bagged, ea | G30: ea | H30: 0 | I30: 6.54 | O30: 45989
A31: Mulch, Soil Pep, Bulk, yd | B31: LMN40150722 | C31: H | E31: Mulch, Soil Pep, Bulk, yd | G31: yd | H31: 0 | I31: 63.08 | O31: 45989
A32: Neem Oil, bottle, ea | B32: NEW020 | C32: H | E32: Neem Oil, bottle, ea | G32: ea | H32: 0 | I32: 42 | J32: 42 | K32: Y | O32: 45988
A33: Netafim, ft | B33: LMN40150664 | C33: H | E33: Netafim, ft | G33: ft | H33: 0 | I33: 0.74 | J33: 0.74 | K33: Y | O33: 45989
A34: Noxious weed control, hr | B34: NEW021 | C34: H | E34: Noxious weed control, hr | G34: hr | H34: 0 | I34: 160 | J34: 160 | K34: Y | O34: 45988
A35: Nozzle, RVAN, ea | B35: NEW038 | C35: H | E35: Nozzle, RVAN, ea | G35: ea | H35: 0 | I35: 12.42 | O35: 45989
A36: Paver Edge | B36: LMN46147072 | C36: H | G36: Ft | H36: 1 | I36: 4.88 | O36: 45847
A37: Peony cages, new, ea | B37: NEW022 | C37: H | E37: Peony cages, new, ea | G37: ea | H37: 0 | I37: 18.99 | J37: 18.99 | K37: Y | O37: 45989
A38: Per Diem, daily, ea | B38: NEW023 | C38: H | E38: Per Diem, daily, ea | G38: ea | H38: 0 | I38: 65 | J38: 65 | K38: Y | O38: 45988
A39: Per Diem, overnight, ea | B39: NEW024 | C39: H | E39: Per Diem, overnight, ea | G39: ea | H39: 0 | I39: 155 | J39: 155 | K39: Y | O39: 45988
A40: Perennial, 1 gal, ea | B40: LMN40150784 | C40: H | E40: Perennial, 1 gal, ea | G40: ea | H40: 0 | I40: 25 | O40: 45989
...
